Time
Status
Host
Request
Messages
Aug 03 17:34:16.90
GET
500
review-pilot-dw83-t159mdo2b-anthony-teslas-projects.vercel.app
/favicon.png
Traceback (most recent call last): File "/var/task/vc__handler__python.py", line 14, in <module> __vc_spec.loader.exec_module(__vc_module) File "<frozen importlib._bootstrap_external>", line 999, in exec_module File "<frozen importlib._bootstrap>", line 488, in _call_with_frames_removed File "/var/task/main.py", line 1, in <module> from app import app File "/var/task/app.py", line 35, in <module> db.init_app(app) File "/var/task/flask_sqlalchemy/extension.py", line 373, in init_app self._apply_driver_defaults(options, app) File "/var/task/flask_sqlalchemy/extension.py", line 607, in _apply_driver_defaults url = sa.engine.make_url(options["url"]) ^^^^^^^^^^^^^^^^^^^^^^^^^^^^^^^^^^ File "/var/task/sqlalchemy/engine/url.py", line 856, in make_url return _parse_url(name_or_url) ^^^^^^^^^^^^^^^^^^^^^^^ File "/var/task/sqlalchemy/engine/url.py", line 922, in _parse_url raise exc.ArgumentError( sqlalchemy.exc.ArgumentError: Could not parse SQLAlchemy URL from given URL string Python process exited with exit status: 1. The logs above can help with debugging the issue.
Aug 03 17:34:12.81
GET
500
review-pilot-dw83-t159mdo2b-anthony-teslas-projects.vercel.app
/favicon.png
Traceback (most recent call last): File "/var/task/vc__handler__python.py", line 14, in <module> __vc_spec.loader.exec_module(__vc_module) File "<frozen importlib._bootstrap_external>", line 999, in exec_module File "<frozen importlib._bootstrap>", line 488, in _call_with_frames_removed File "/var/task/main.py", line 1, in <module> from app import app File "/var/task/app.py", line 35, in <module> db.init_app(app) File "/var/task/flask_sqlalchemy/extension.py", line 373, in init_app self._apply_driver_defaults(options, app) File "/var/task/flask_sqlalchemy/extension.py", line 607, in _apply_driver_defaults url = sa.engine.make_url(options["url"]) ^^^^^^^^^^^^^^^^^^^^^^^^^^^^^^^^^^ File "/var/task/sqlalchemy/engine/url.py", line 856, in make_url return _parse_url(name_or_url) ^^^^^^^^^^^^^^^^^^^^^^^ File "/var/task/sqlalchemy/engine/url.py", line 922, in _parse_url raise exc.ArgumentError( sqlalchemy.exc.ArgumentError: Could not parse SQLAlchemy URL from given URL string Python process exited with exit status: 1. The logs above can help with debugging the issue.
Aug 03 17:34:09.64
GET
500
review-pilot-dw83-t159mdo2b-anthony-teslas-projects.vercel.app
/favicon.png
Traceback (most recent call last): File "/var/task/vc__handler__python.py", line 14, in <module> __vc_spec.loader.exec_module(__vc_module) File "<frozen importlib._bootstrap_external>", line 999, in exec_module File "<frozen importlib._bootstrap>", line 488, in _call_with_frames_removed File "/var/task/main.py", line 1, in <module> from app import app File "/var/task/app.py", line 35, in <module> db.init_app(app) File "/var/task/flask_sqlalchemy/extension.py", line 373, in init_app self._apply_driver_defaults(options, app) File "/var/task/flask_sqlalchemy/extension.py", line 607, in _apply_driver_defaults url = sa.engine.make_url(options["url"]) ^^^^^^^^^^^^^^^^^^^^^^^^^^^^^^^^^^ File "/var/task/sqlalchemy/engine/url.py", line 856, in make_url return _parse_url(name_or_url) ^^^^^^^^^^^^^^^^^^^^^^^ File "/var/task/sqlalchemy/engine/url.py", line 922, in _parse_url raise exc.ArgumentError( sqlalchemy.exc.ArgumentError: Could not parse SQLAlchemy URL from given URL string Python process exited with exit status: 1. The logs above can help with debugging the issue.
Aug 03 17:34:07.53
GET
500
review-pilot-dw83-t159mdo2b-anthony-teslas-projects.vercel.app
/favicon.ico
Traceback (most recent call last): File "/var/task/vc__handler__python.py", line 14, in <module> __vc_spec.loader.exec_module(__vc_module) File "<frozen importlib._bootstrap_external>", line 999, in exec_module File "<frozen importlib._bootstrap>", line 488, in _call_with_frames_removed File "/var/task/main.py", line 1, in <module> from app import app File "/var/task/app.py", line 35, in <module> db.init_app(app) File "/var/task/flask_sqlalchemy/extension.py", line 373, in init_app self._apply_driver_defaults(options, app) File "/var/task/flask_sqlalchemy/extension.py", line 607, in _apply_driver_defaults url = sa.engine.make_url(options["url"]) ^^^^^^^^^^^^^^^^^^^^^^^^^^^^^^^^^^ File "/var/task/sqlalchemy/engine/url.py", line 856, in make_url return _parse_url(name_or_url) ^^^^^^^^^^^^^^^^^^^^^^^ File "/var/task/sqlalchemy/engine/url.py", line 922, in _parse_url raise exc.ArgumentError( sqlalchemy.exc.ArgumentError: Could not parse SQLAlchemy URL from given URL string Python process exited with exit status: 1. The logs above can help with debugging the issue.
Aug 03 17:34:03.12
GET
500
review-pilot-dw83-t159mdo2b-anthony-teslas-projects.vercel.app
/favicon.ico
Traceback (most recent call last): File "/var/task/vc__handler__python.py", line 14, in <module> __vc_spec.loader.exec_module(__vc_module) File "<frozen importlib._bootstrap_external>", line 999, in exec_module File "<frozen importlib._bootstrap>", line 488, in _call_with_frames_removed File "/var/task/main.py", line 1, in <module> from app import app File "/var/task/app.py", line 35, in <module> db.init_app(app) File "/var/task/flask_sqlalchemy/extension.py", line 373, in init_app self._apply_driver_defaults(options, app) File "/var/task/flask_sqlalchemy/extension.py", line 607, in _apply_driver_defaults url = sa.engine.make_url(options["url"]) ^^^^^^^^^^^^^^^^^^^^^^^^^^^^^^^^^^ File "/var/task/sqlalchemy/engine/url.py", line 856, in make_url return _parse_url(name_or_url) ^^^^^^^^^^^^^^^^^^^^^^^ File "/var/task/sqlalchemy/engine/url.py", line 922, in _parse_url raise exc.ArgumentError( sqlalchemy.exc.ArgumentError: Could not parse SQLAlchemy URL from given URL string Python process exited with exit status: 1. The logs above can help with debugging the issue.
Aug 03 17:34:00.04
GET
500
review-pilot-dw83-t159mdo2b-anthony-teslas-projects.vercel.app
/favicon.ico
Traceback (most recent call last): File "/var/task/vc__handler__python.py", line 14, in <module> __vc_spec.loader.exec_module(__vc_module) File "<frozen importlib._bootstrap_external>", line 999, in exec_module File "<frozen importlib._bootstrap>", line 488, in _call_with_frames_removed File "/var/task/main.py", line 1, in <module> from app import app File "/var/task/app.py", line 35, in <module> db.init_app(app) File "/var/task/flask_sqlalchemy/extension.py", line 373, in init_app self._apply_driver_defaults(options, app) File "/var/task/flask_sqlalchemy/extension.py", line 607, in _apply_driver_defaults url = sa.engine.make_url(options["url"]) ^^^^^^^^^^^^^^^^^^^^^^^^^^^^^^^^^^ File "/var/task/sqlalchemy/engine/url.py", line 856, in make_url return _parse_url(name_or_url) ^^^^^^^^^^^^^^^^^^^^^^^ File "/var/task/sqlalchemy/engine/url.py", line 922, in _parse_url raise exc.ArgumentError( sqlalchemy.exc.ArgumentError: Could not parse SQLAlchemy URL from given URL string Python process exited with exit status: 1. The logs above can help with debugging the issue.
Aug 03 17:33:57.89
GET
500
review-pilot-dw83-t159mdo2b-anthony-teslas-projects.vercel.app
/
Traceback (most recent call last): File "/var/task/vc__handler__python.py", line 14, in <module> __vc_spec.loader.exec_module(__vc_module) File "<frozen importlib._bootstrap_external>", line 999, in exec_module File "<frozen importlib._bootstrap>", line 488, in _call_with_frames_removed File "/var/task/main.py", line 1, in <module> from app import app File "/var/task/app.py", line 35, in <module> db.init_app(app) File "/var/task/flask_sqlalchemy/extension.py", line 373, in init_app self._apply_driver_defaults(options, app) File "/var/task/flask_sqlalchemy/extension.py", line 607, in _apply_driver_defaults url = sa.engine.make_url(options["url"]) ^^^^^^^^^^^^^^^^^^^^^^^^^^^^^^^^^^ File "/var/task/sqlalchemy/engine/url.py", line 856, in make_url return _parse_url(name_or_url) ^^^^^^^^^^^^^^^^^^^^^^^ File "/var/task/sqlalchemy/engine/url.py", line 922, in _parse_url raise exc.ArgumentError( sqlalchemy.exc.ArgumentError: Could not parse SQLAlchemy URL from given URL string Python process exited with exit status: 1. The logs above can help with debugging the issue.
Aug 03 17:33:54.84
GET
500
review-pilot-dw83-t159mdo2b-anthony-teslas-projects.vercel.app
/
Traceback (most recent call last): File "/var/task/vc__handler__python.py", line 14, in <module> __vc_spec.loader.exec_module(__vc_module) File "<frozen importlib._bootstrap_external>", line 999, in exec_module File "<frozen importlib._bootstrap>", line 488, in _call_with_frames_removed File "/var/task/main.py", line 1, in <module> from app import app File "/var/task/app.py", line 35, in <module> db.init_app(app) File "/var/task/flask_sqlalchemy/extension.py", line 373, in init_app self._apply_driver_defaults(options, app) File "/var/task/flask_sqlalchemy/extension.py", line 607, in _apply_driver_defaults url = sa.engine.make_url(options["url"]) ^^^^^^^^^^^^^^^^^^^^^^^^^^^^^^^^^^ File "/var/task/sqlalchemy/engine/url.py", line 856, in make_url return _parse_url(name_or_url) ^^^^^^^^^^^^^^^^^^^^^^^ File "/var/task/sqlalchemy/engine/url.py", line 922, in _parse_url raise exc.ArgumentError( sqlalchemy.exc.ArgumentError: Could not parse SQLAlchemy URL from given URL string Python process exited with exit status: 1. The logs above can help with debugging the issue.
Aug 03 17:33:38.29
GET
500
review-pilot-dw83-t159mdo2b-anthony-teslas-projects.vercel.app
/favicon.ico
Traceback (most recent call last): File "/var/task/vc__handler__python.py", line 14, in <module> __vc_spec.loader.exec_module(__vc_module) File "<frozen importlib._bootstrap_external>", line 999, in exec_module File "<frozen importlib._bootstrap>", line 488, in _call_with_frames_removed File "/var/task/main.py", line 1, in <module> from app import app File "/var/task/app.py", line 35, in <module> db.init_app(app) File "/var/task/flask_sqlalchemy/extension.py", line 373, in init_app self._apply_driver_defaults(options, app) File "/var/task/flask_sqlalchemy/extension.py", line 607, in _apply_driver_defaults url = sa.engine.make_url(options["url"]) ^^^^^^^^^^^^^^^^^^^^^^^^^^^^^^^^^^ File "/var/task/sqlalchemy/engine/url.py", line 856, in make_url return _parse_url(name_or_url) ^^^^^^^^^^^^^^^^^^^^^^^ File "/var/task/sqlalchemy/engine/url.py", line 922, in _parse_url raise exc.ArgumentError( sqlalchemy.exc.ArgumentError: Could not parse SQLAlchemy URL from given URL string Python process exited with exit status: 1. The logs above can help with debugging the issue.
Aug 03 17:33:36.05
GET
500
review-pilot-dw83-t159mdo2b-anthony-teslas-projects.vercel.app
/favicon.ico
Traceback (most recent call last): File "/var/task/vc__handler__python.py", line 14, in <module> __vc_spec.loader.exec_module(__vc_module) File "<frozen importlib._bootstrap_external>", line 999, in exec_module File "<frozen importlib._bootstrap>", line 488, in _call_with_frames_removed File "/var/task/main.py", line 1, in <module> from app import app File "/var/task/app.py", line 35, in <module> db.init_app(app) File "/var/task/flask_sqlalchemy/extension.py", line 373, in init_app self._apply_driver_defaults(options, app) File "/var/task/flask_sqlalchemy/extension.py", line 607, in _apply_driver_defaults url = sa.engine.make_url(options["url"]) ^^^^^^^^^^^^^^^^^^^^^^^^^^^^^^^^^^ File "/var/task/sqlalchemy/engine/url.py", line 856, in make_url return _parse_url(name_or_url) ^^^^^^^^^^^^^^^^^^^^^^^ File "/var/task/sqlalchemy/engine/url.py", line 922, in _parse_url raise exc.ArgumentError( sqlalchemy.exc.ArgumentError: Could not parse SQLAlchemy URL from given URL string Python process exited with exit status: 1. The logs above can help with debugging the issue.
Aug 03 17:33:33.83
GET
500
review-pilot-dw83-t159mdo2b-anthony-teslas-projects.vercel.app
/
Traceback (most recent call last): File "/var/task/vc__handler__python.py", line 14, in <module> __vc_spec.loader.exec_module(__vc_module) File "<frozen importlib._bootstrap_external>", line 999, in exec_module File "<frozen importlib._bootstrap>", line 488, in _call_with_frames_removed File "/var/task/main.py", line 1, in <module> from app import app File "/var/task/app.py", line 35, in <module> db.init_app(app) File "/var/task/flask_sqlalchemy/extension.py", line 373, in init_app self._apply_driver_defaults(options, app) File "/var/task/flask_sqlalchemy/extension.py", line 607, in _apply_driver_defaults url = sa.engine.make_url(options["url"]) ^^^^^^^^^^^^^^^^^^^^^^^^^^^^^^^^^^ File "/var/task/sqlalchemy/engine/url.py", line 856, in make_url return _parse_url(name_or_url) ^^^^^^^^^^^^^^^^^^^^^^^ File "/var/task/sqlalchemy/engine/url.py", line 922, in _parse_url raise exc.ArgumentError( sqlalchemy.exc.ArgumentError: Could not parse SQLAlchemy URL from given URL string Python process exited with exit status: 1. The logs above can help with debugging the issue.
Aug 03 17:33:33.79
GET
500
review-pilot-dw83-t159mdo2b-anthony-teslas-projects.vercel.app
/
Traceback (most recent call last): File "/var/task/vc__handler__python.py", line 14, in <module> __vc_spec.loader.exec_module(__vc_module) File "<frozen importlib._bootstrap_external>", line 999, in exec_module File "<frozen importlib._bootstrap>", line 488, in _call_with_frames_removed File "/var/task/main.py", line 1, in <module> from app import app File "/var/task/app.py", line 35, in <module> db.init_app(app) File "/var/task/flask_sqlalchemy/extension.py", line 373, in init_app self._apply_driver_defaults(options, app) File "/var/task/flask_sqlalchemy/extension.py", line 607, in _apply_driver_defaults url = sa.engine.make_url(options["url"]) ^^^^^^^^^^^^^^^^^^^^^^^^^^^^^^^^^^ File "/var/task/sqlalchemy/engine/url.py", line 856, in make_url return _parse_url(name_or_url) ^^^^^^^^^^^^^^^^^^^^^^^ File "/var/task/sqlalchemy/engine/url.py", line 922, in _parse_url raise exc.ArgumentError( sqlalchemy.exc.ArgumentError: Could not parse SQLAlchemy URL from given URL string Python process exited with exit status: 1. The logs above can help with debugging the issue. Traceback (most recent call last): File "/var/task/vc__handler__python.py", line 14, in <module> __vc_spec.loader.exec_module(__vc_module) File "<frozen importlib._bootstrap_external>", line 999, in exec_module File "<frozen importlib._bootstrap>", line 488, in _call_with_frames_removed File "/var/task/main.py", line 1, in <module> from app import app File "/var/task/app.py", line 35, in <module> db.init_app(app) File "/var/task/flask_sqlalchemy/extension.py", line 373, in init_app self._apply_driver_defaults(options, app) File "/var/task/flask_sqlalchemy/extension.py", line 607, in _apply_driver_defaults url = sa.engine.make_url(options["url"]) ^^^^^^^^^^^^^^^^^^^^^^^^^^^^^^^^^^ File "/var/task/sqlalchemy/engine/url.py", line 856, in make_url return _parse_url(name_or_url) ^^^^^^^^^^^^^^^^^^^^^^^ File "/var/task/sqlalchemy/engine/url.py", line 922, in _parse_url raise exc.ArgumentError( sqlalchemy.exc.ArgumentError: Could not parse SQLAlchemy URL from given URL string Python process exited with exit status: 1. The logs above can help with debugging the issue.
Aug 03 17:33:29.78
GET
500
review-pilot-dw83-t159mdo2b-anthony-teslas-projects.vercel.app
/
Traceback (most recent call last): File "/var/task/vc__handler__python.py", line 14, in <module> __vc_spec.loader.exec_module(__vc_module) File "<frozen importlib._bootstrap_external>", line 999, in exec_module File "<frozen importlib._bootstrap>", line 488, in _call_with_frames_removed File "/var/task/main.py", line 1, in <module> from app import app File "/var/task/app.py", line 35, in <module> db.init_app(app) File "/var/task/flask_sqlalchemy/extension.py", line 373, in init_app self._apply_driver_defaults(options, app) File "/var/task/flask_sqlalchemy/extension.py", line 607, in _apply_driver_defaults url = sa.engine.make_url(options["url"]) ^^^^^^^^^^^^^^^^^^^^^^^^^^^^^^^^^^ File "/var/task/sqlalchemy/engine/url.py", line 856, in make_url return _parse_url(name_or_url) ^^^^^^^^^^^^^^^^^^^^^^^ File "/var/task/sqlalchemy/engine/url.py", line 922, in _parse_url raise exc.ArgumentError( sqlalchemy.exc.ArgumentError: Could not parse SQLAlchemy URL from given URL string Python process exited with exit status: 1. The logs above can help with debugging the issue. Traceback (most recent call last): File "/var/task/vc__handler__python.py", line 14, in <module> __vc_spec.loader.exec_module(__vc_module) File "<frozen importlib._bootstrap_external>", line 999, in exec_module File "<frozen importlib._bootstrap>", line 488, in _call_with_frames_removed File "/var/task/main.py", line 1, in <module> from app import app File "/var/task/app.py", line 35, in <module> db.init_app(app) File "/var/task/flask_sqlalchemy/extension.py", line 373, in init_app self._apply_driver_defaults(options, app) File "/var/task/flask_sqlalchemy/extension.py", line 607, in _apply_driver_defaults url = sa.engine.make_url(options["url"]) ^^^^^^^^^^^^^^^^^^^^^^^^^^^^^^^^^^ File "/var/task/sqlalchemy/engine/url.py", line 856, in make_url return _parse_url(name_or_url) ^^^^^^^^^^^^^^^^^^^^^^^ File "/var/task/sqlalchemy/engine/url.py", line 922, in _parse_url raise exc.ArgumentError( sqlalchemy.exc.ArgumentError: Could not parse SQLAlchemy URL from given URL string Python process exited with exit status: 1. The logs above can help with debugging the issue.
Aug 03 17:33:29.77
GET
500
review-pilot-dw83-t159mdo2b-anthony-teslas-projects.vercel.app
/
Traceback (most recent call last): File "/var/task/vc__handler__python.py", line 14, in <module> __vc_spec.loader.exec_module(__vc_module) File "<frozen importlib._bootstrap_external>", line 999, in exec_module File "<frozen importlib._bootstrap>", line 488, in _call_with_frames_removed File "/var/task/main.py", line 1, in <module> from app import app File "/var/task/app.py", line 35, in <module> db.init_app(app) File "/var/task/flask_sqlalchemy/extension.py", line 373, in init_app self._apply_driver_defaults(options, app) File "/var/task/flask_sqlalchemy/extension.py", line 607, in _apply_driver_defaults url = sa.engine.make_url(options["url"]) ^^^^^^^^^^^^^^^^^^^^^^^^^^^^^^^^^^ File "/var/task/sqlalchemy/engine/url.py", line 856, in make_url return _parse_url(name_or_url) ^^^^^^^^^^^^^^^^^^^^^^^ File "/var/task/sqlalchemy/engine/url.py", line 922, in _parse_url raise exc.ArgumentError( sqlalchemy.exc.ArgumentError: Could not parse SQLAlchemy URL from given URL string Python process exited with exit status: 1. The logs above can help with debugging the issue. Traceback (most recent call last): File "/var/task/vc__handler__python.py", line 14, in <module> __vc_spec.loader.exec_module(__vc_module) File "<frozen importlib._bootstrap_external>", line 999, in exec_module File "<frozen importlib._bootstrap>", line 488, in _call_with_frames_removed File "/var/task/main.py", line 1, in <module> from app import app File "/var/task/app.py", line 35, in <module> db.init_app(app) File "/var/task/flask_sqlalchemy/extension.py", line 373, in init_app self._apply_driver_defaults(options, app) File "/var/task/flask_sqlalchemy/extension.py", line 607, in _apply_driver_defaults url = sa.engine.make_url(options["url"]) ^^^^^^^^^^^^^^^^^^^^^^^^^^^^^^^^^^ File "/var/task/sqlalchemy/engine/url.py", line 856, in make_url return _parse_url(name_or_url) ^^^^^^^^^^^^^^^^^^^^^^^ File "/var/task/sqlalchemy/engine/url.py", line 922, in _parse_url raise exc.ArgumentError( sqlalchemy.exc.ArgumentError: Could not parse SQLAlchemy URL from given URL string Python process exited with exit status: 1. The logs above can help with debugging the issue.
No more logs to show within selected timeline